<testng-results>
  <reporter-output>
  </reporter-output>
  <suite name="My suite" duration-ms="0" started-at="2015-10-12T19:46:55Z" finished-at="2015-10-12T19:46:55Z">
    <groups>
    </groups>
  </suite>
  <suite name="Suite B" duration-ms="85" started-at="2015-10-12T19:46:54Z" finished-at="2015-10-12T19:46:54Z">
    <groups>
    </groups>
    <test name="Test B1" duration-ms="8" started-at="2015-10-12T19:46:54Z" finished-at="2015-10-12T19:46:54Z">
      <class name="testSuiteB.TestB1">
        <test-method status="PASS" signature="testB1_1()" name="testB1_1" duration-ms="0" started-at="2015-10-12T19:46:54Z" finished-at="2015-10-12T19:46:54Z">
        </test-method>
        <test-method status="PASS" signature="testB1_2()" name="testB1_2" duration-ms="1" started-at="2015-10-12T19:46:54Z" finished-at="2015-10-12T19:46:54Z">
        </test-method>
        <test-method status="FAIL" signature="testB1_3()" name="testB1_3" duration-ms="1" started-at="2015-10-12T19:46:54Z" finished-at="2015-10-12T19:46:54Z">
          <exception class="java.lang.AssertionError">
            <message>
              <![CDATA[failed test case ]]>
            </message>
            <full-stacktrace>
              <![CDATA[java.lang.AssertionError: failed test case 
	at org.testng.Assert.fail(Assert.java:89)
	at testSuiteB.TestB1.testB1_3(TestB1.java:22)
	at sun.reflect.NativeMethodAccessorImpl.invoke0(Native Method)
	at sun.reflect.NativeMethodAccessorImpl.invoke(NativeMethodAccessorImpl.java:57)
	at sun.reflect.DelegatingMethodAccessorImpl.invoke(DelegatingMethodAccessorImpl.java:43)
	at java.lang.reflect.Method.invoke(Method.java:606)
	at org.testng.internal.MethodInvocationHelper.invokeMethod(MethodInvocationHelper.java:74)
	at org.testng.internal.Invoker.invokeMethod(Invoker.java:673)
	at org.testng.internal.Invoker.invokeTestMethod(Invoker.java:846)
	at org.testng.internal.Invoker.invokeTestMethods(Invoker.java:1170)
	at org.testng.internal.TestMethodWorker.invokeTestMethods(TestMethodWorker.java:125)
	at org.testng.internal.TestMethodWorker.run(TestMethodWorker.java:109)
	at org.testng.TestRunner.runWorkers(TestRunner.java:1125)
	at org.testng.TestRunner.privateRun(TestRunner.java:749)
	at org.testng.TestRunner.run(TestRunner.java:600)
	at org.testng.SuiteRunner.runTest(SuiteRunner.java:317)
	at org.testng.SuiteRunner.runSequentially(SuiteRunner.java:312)
	at org.testng.SuiteRunner.privateRun(SuiteRunner.java:274)
	at org.testng.SuiteRunner.run(SuiteRunner.java:223)
	at org.testng.SuiteRunnerWorker.runSuite(SuiteRunnerWorker.java:52)
	at org.testng.SuiteRunnerWorker.run(SuiteRunnerWorker.java:86)
	at org.testng.TestNG.runSuitesSequentially(TestNG.java:965)
	at org.testng.TestNG.runSuitesSequentially(TestNG.java:961)
	at org.testng.TestNG.runSuitesLocally(TestNG.java:890)
	at org.testng.TestNG.run(TestNG.java:824)
	at org.testng.TestNG.privateMain(TestNG.java:1128)
	at org.testng.TestNG.main(TestNG.java:1092)
]]>
            </full-stacktrace>
          </exception>
        </test-method>
      </class>
    </test>
    <test name="Test B2" duration-ms="8" started-at="2015-10-12T19:46:54Z" finished-at="2015-10-12T19:46:54Z">
      <class name="testSuiteB.TestB2">
        <test-method status="PASS" signature="testB2_1()" name="testB2_1" duration-ms="0" started-at="2015-10-12T19:46:54Z" finished-at="2015-10-12T19:46:54Z">
        </test-method>
        <test-method status="FAIL" signature="testB2_2()" name="testB2_2" duration-ms="1" started-at="2015-10-12T19:46:54Z" finished-at="2015-10-12T19:46:54Z">
          <exception class="java.lang.AssertionError">
            <message>
              <![CDATA[failed test case ]]>
            </message>
            <full-stacktrace>
              <![CDATA[java.lang.AssertionError: failed test case 
	at org.testng.Assert.fail(Assert.java:89)
	at testSuiteB.TestB2.testB2_2(TestB2.java:16)
	at sun.reflect.NativeMethodAccessorImpl.invoke0(Native Method)
	at sun.reflect.NativeMethodAccessorImpl.invoke(NativeMethodAccessorImpl.java:57)
	at sun.reflect.DelegatingMethodAccessorImpl.invoke(DelegatingMethodAccessorImpl.java:43)
	at java.lang.reflect.Method.invoke(Method.java:606)
	at org.testng.internal.MethodInvocationHelper.invokeMethod(MethodInvocationHelper.java:74)
	at org.testng.internal.Invoker.invokeMethod(Invoker.java:673)
	at org.testng.internal.Invoker.invokeTestMethod(Invoker.java:846)
	at org.testng.internal.Invoker.invokeTestMethods(Invoker.java:1170)
	at org.testng.internal.TestMethodWorker.invokeTestMethods(TestMethodWorker.java:125)
	at org.testng.internal.TestMethodWorker.run(TestMethodWorker.java:109)
	at org.testng.TestRunner.runWorkers(TestRunner.java:1125)
	at org.testng.TestRunner.privateRun(TestRunner.java:749)
	at org.testng.TestRunner.run(TestRunner.java:600)
	at org.testng.SuiteRunner.runTest(SuiteRunner.java:317)
	at org.testng.SuiteRunner.runSequentially(SuiteRunner.java:312)
	at org.testng.SuiteRunner.privateRun(SuiteRunner.java:274)
	at org.testng.SuiteRunner.run(SuiteRunner.java:223)
	at org.testng.SuiteRunnerWorker.runSuite(SuiteRunnerWorker.java:52)
	at org.testng.SuiteRunnerWorker.run(SuiteRunnerWorker.java:86)
	at org.testng.TestNG.runSuitesSequentially(TestNG.java:965)
	at org.testng.TestNG.runSuitesSequentially(TestNG.java:961)
	at org.testng.TestNG.runSuitesLocally(TestNG.java:890)
	at org.testng.TestNG.run(TestNG.java:824)
	at org.testng.TestNG.privateMain(TestNG.java:1128)
	at org.testng.TestNG.main(TestNG.java:1092)
]]>
            </full-stacktrace>
          </exception>
        </test-method>
        <test-method status="PASS" signature="testB2_3()" name="testB2_3" duration-ms="0" started-at="2015-10-12T19:46:54Z" finished-at="2015-10-12T19:46:54Z">
        </test-method>
      </class>
    </test>
  </suite>
  <suite name="Suite A" duration-ms="2337" started-at="2015-10-12T19:46:52Z" finished-at="2015-10-12T19:46:54Z">
    <groups>
    </groups>
    <test name="Test A1" duration-ms="89" started-at="2015-10-12T19:46:52Z" finished-at="2015-10-12T19:46:52Z">
      <class name="testSuiteA.TestA1">
        <test-method status="SKIP" signature="testA1_1()" name="testA1_1" duration-ms="65" started-at="2015-10-12T19:46:52Z" finished-at="2015-10-12T19:46:52Z">
          <exception class="org.testng.SkipException">
            <message>
              <![CDATA[Skipping the test]]>
            </message>
            <full-stacktrace>
              <![CDATA[org.testng.SkipException: Skipping the test
	at testSuiteA.TestA1.testA1_1(TestA1.java:12)
	at sun.reflect.NativeMethodAccessorImpl.invoke0(Native Method)
	at sun.reflect.NativeMethodAccessorImpl.invoke(NativeMethodAccessorImpl.java:57)
	at sun.reflect.DelegatingMethodAccessorImpl.invoke(DelegatingMethodAccessorImpl.java:43)
	at java.lang.reflect.Method.invoke(Method.java:606)
	at org.testng.internal.MethodInvocationHelper.invokeMethod(MethodInvocationHelper.java:74)
	at org.testng.internal.Invoker.invokeMethod(Invoker.java:673)
	at org.testng.internal.Invoker.invokeTestMethod(Invoker.java:846)
	at org.testng.internal.Invoker.invokeTestMethods(Invoker.java:1170)
	at org.testng.internal.TestMethodWorker.invokeTestMethods(TestMethodWorker.java:125)
	at org.testng.internal.TestMethodWorker.run(TestMethodWorker.java:109)
	at org.testng.TestRunner.runWorkers(TestRunner.java:1125)
	at org.testng.TestRunner.privateRun(TestRunner.java:749)
	at org.testng.TestRunner.run(TestRunner.java:600)
	at org.testng.SuiteRunner.runTest(SuiteRunner.java:317)
	at org.testng.SuiteRunner.runSequentially(SuiteRunner.java:312)
	at org.testng.SuiteRunner.privateRun(SuiteRunner.java:274)
	at org.testng.SuiteRunner.run(SuiteRunner.java:223)
	at org.testng.SuiteRunnerWorker.runSuite(SuiteRunnerWorker.java:52)
	at org.testng.SuiteRunnerWorker.run(SuiteRunnerWorker.java:86)
	at org.testng.TestNG.runSuitesSequentially(TestNG.java:965)
	at org.testng.TestNG.runSuitesSequentially(TestNG.java:961)
	at org.testng.TestNG.runSuitesLocally(TestNG.java:890)
	at org.testng.TestNG.run(TestNG.java:824)
	at org.testng.TestNG.privateMain(TestNG.java:1128)
	at org.testng.TestNG.main(TestNG.java:1092)
]]>
            </full-stacktrace>
          </exception>
        </test-method>
        <test-method status="PASS" signature="testA1_2()" name="testA1_2" duration-ms="0" started-at="2015-10-12T19:46:52Z" finished-at="2015-10-12T19:46:52Z">
        </test-method>
        <test-method status="FAIL" signature="testA1_3()" name="testA1_3" duration-ms="4" started-at="2015-10-12T19:46:52Z" finished-at="2015-10-12T19:46:52Z">
          <exception class="java.lang.AssertionError">
            <message>
              <![CDATA[failed test case ]]>
            </message>
            <full-stacktrace>
              <![CDATA[java.lang.AssertionError: failed test case 
	at org.testng.Assert.fail(Assert.java:89)
	at testSuiteA.TestA1.testA1_3(TestA1.java:23)
	at sun.reflect.NativeMethodAccessorImpl.invoke0(Native Method)
	at sun.reflect.NativeMethodAccessorImpl.invoke(NativeMethodAccessorImpl.java:57)
	at sun.reflect.DelegatingMethodAccessorImpl.invoke(DelegatingMethodAccessorImpl.java:43)
	at java.lang.reflect.Method.invoke(Method.java:606)
	at org.testng.internal.MethodInvocationHelper.invokeMethod(MethodInvocationHelper.java:74)
	at org.testng.internal.Invoker.invokeMethod(Invoker.java:673)
	at org.testng.internal.Invoker.invokeTestMethod(Invoker.java:846)
	at org.testng.internal.Invoker.invokeTestMethods(Invoker.java:1170)
	at org.testng.internal.TestMethodWorker.invokeTestMethods(TestMethodWorker.java:125)
	at org.testng.internal.TestMethodWorker.run(TestMethodWorker.java:109)
	at org.testng.TestRunner.runWorkers(TestRunner.java:1125)
	at org.testng.TestRunner.privateRun(TestRunner.java:749)
	at org.testng.TestRunner.run(TestRunner.java:600)
	at org.testng.SuiteRunner.runTest(SuiteRunner.java:317)
	at org.testng.SuiteRunner.runSequentially(SuiteRunner.java:312)
	at org.testng.SuiteRunner.privateRun(SuiteRunner.java:274)
	at org.testng.SuiteRunner.run(SuiteRunner.java:223)
	at org.testng.SuiteRunnerWorker.runSuite(SuiteRunnerWorker.java:52)
	at org.testng.SuiteRunnerWorker.run(SuiteRunnerWorker.java:86)
	at org.testng.TestNG.runSuitesSequentially(TestNG.java:965)
	at org.testng.TestNG.runSuitesSequentially(TestNG.java:961)
	at org.testng.TestNG.runSuitesLocally(TestNG.java:890)
	at org.testng.TestNG.run(TestNG.java:824)
	at org.testng.TestNG.privateMain(TestNG.java:1128)
	at org.testng.TestNG.main(TestNG.java:1092)
]]>
            </full-stacktrace>
          </exception>
        </test-method>
      </class>
    </test>
    <test name="Test A2" duration-ms="7" started-at="2015-10-12T19:46:54Z" finished-at="2015-10-12T19:46:54Z">
      <class name="testSuiteA.TestA2">
        <test-method status="PASS" signature="testA2_1()" name="testA2_1" duration-ms="0" started-at="2015-10-12T19:46:54Z" finished-at="2015-10-12T19:46:54Z">
        </test-method>
        <test-method status="FAIL" signature="testA2_2()" name="testA2_2" duration-ms="1" started-at="2015-10-12T19:46:54Z" finished-at="2015-10-12T19:46:54Z">
          <exception class="java.lang.AssertionError">
            <message>
              <![CDATA[failed test case ]]>
            </message>
            <full-stacktrace>
              <![CDATA[java.lang.AssertionError: failed test case 
	at org.testng.Assert.fail(Assert.java:89)
	at testSuiteA.TestA2.testA2_2(TestA2.java:16)
	at sun.reflect.NativeMethodAccessorImpl.invoke0(Native Method)
	at sun.reflect.NativeMethodAccessorImpl.invoke(NativeMethodAccessorImpl.java:57)
	at sun.reflect.DelegatingMethodAccessorImpl.invoke(DelegatingMethodAccessorImpl.java:43)
	at java.lang.reflect.Method.invoke(Method.java:606)
	at org.testng.internal.MethodInvocationHelper.invokeMethod(MethodInvocationHelper.java:74)
	at org.testng.internal.Invoker.invokeMethod(Invoker.java:673)
	at org.testng.internal.Invoker.invokeTestMethod(Invoker.java:846)
	at org.testng.internal.Invoker.invokeTestMethods(Invoker.java:1170)
	at org.testng.internal.TestMethodWorker.invokeTestMethods(TestMethodWorker.java:125)
	at org.testng.internal.TestMethodWorker.run(TestMethodWorker.java:109)
	at org.testng.TestRunner.runWorkers(TestRunner.java:1125)
	at org.testng.TestRunner.privateRun(TestRunner.java:749)
	at org.testng.TestRunner.run(TestRunner.java:600)
	at org.testng.SuiteRunner.runTest(SuiteRunner.java:317)
	at org.testng.SuiteRunner.runSequentially(SuiteRunner.java:312)
	at org.testng.SuiteRunner.privateRun(SuiteRunner.java:274)
	at org.testng.SuiteRunner.run(SuiteRunner.java:223)
	at org.testng.SuiteRunnerWorker.runSuite(SuiteRunnerWorker.java:52)
	at org.testng.SuiteRunnerWorker.run(SuiteRunnerWorker.java:86)
	at org.testng.TestNG.runSuitesSequentially(TestNG.java:965)
	at org.testng.TestNG.runSuitesSequentially(TestNG.java:961)
	at org.testng.TestNG.runSuitesLocally(TestNG.java:890)
	at org.testng.TestNG.run(TestNG.java:824)
	at org.testng.TestNG.privateMain(TestNG.java:1128)
	at org.testng.TestNG.main(TestNG.java:1092)
]]>
            </full-stacktrace>
          </exception>
        </test-method>
        <test-method status="PASS" signature="testA2_3()" name="testA2_3" duration-ms="0" started-at="2015-10-12T19:46:54Z" finished-at="2015-10-12T19:46:54Z">
        </test-method>
      </class>
    </test>
  </suite>
</testng-results>
